Workbook

Sheet Trials
A1: Date | B1: Day | C1: Club | D1: City | E1: State | F1: AKC event # | G1: Scope | H1: LC Trial entries | I1: LC Trial competitors | J1: LC Test entries (JC/QC) | K1: LC Test competitors | L1: Total entries | M1: Results posted | N1: AKC event page
A2: 46025 | B2: =TEXT(A2,"ddd") -> Sat | C2: Sunshine State Rhodesian Ridgeback Club | D2: Weirsdale | E2: FL | F2: 2026702901 | G2: All-breed | H2: 35 | I2: 34 | J2: 12 | K2: 12 | L2: =IF(M2="Yes",SUM(H2,J2),"") -> 47 | M2: Yes | N2: Open
A3: 46026 | B3: =TEXT(A3,"ddd") -> Sun | C3: Sunshine State Rhodesian Ridgeback Club | D3: Weirsdale | E3: FL | F3: 2026702902 | G3: All-breed | H3: 41 | I3: 37 | J3: 2 | K3: 2 | L3: =IF(M3="Yes",SUM(H3,J3),"") -> 43 | M3: Yes | N3: Open
A4: 46032 | B4: =TEXT(A4,"ddd") -> Sat | C4: Northern California Whippet Fanciers Association | D4: Elverta | E4: CA | F4: 2026264102 | G4: All-breed | H4: 59 | I4: 59 | J4: 14 | K4: 14 | L4: =IF(M4="Yes",SUM(H4,J4),"") -> 73 | M4: Yes | N4: Open
A5: 46033 | B5: =TEXT(A5,"ddd") -> Sun | C5: Northern California Whippet Fanciers Association | D5: Elverta | E5: CA | F5: 2026264101 | G5: All-breed | H5: 61 | I5: 61 | J5: 8 | K5: 8 | L5: =IF(M5="Yes",SUM(H5,J5),"") -> 69 | M5: Yes | N5: Open
A6: 46039 | B6: =TEXT(A6,"ddd") -> Sat | C6: Desert Fun Bunch Sighthound Club | D6: Black Canyon City | E6: AZ | F6: 2026572902 | G6: All-breed | H6: 41 | I6: 41 | J6: 2 | K6: 2 | L6: =IF(M6="Yes",SUM(H6,J6),"") -> 43 | M6: Yes | N6: Open
A7: 46039 | B7: =TEXT(A7,"ddd") -> Sat | C7: Afghan Hound Club of Dallas | D7: Celina | E7: TX | F7: 2026073806 | G7: All-breed | H7: 24 | I7: 23 | J7: 5 | K7: 5 | L7: =IF(M7="Yes",SUM(H7,J7),"") -> 29 | M7: Yes | N7: Open
A8: 46040 | B8: =TEXT(A8,"ddd") -> Sun | C8: Desert Fun Bunch Sighthound Club | D8: Black Canyon City | E8: AZ | F8: 2026572901 | G8: All-breed | H8: 39 | I8: 39 | J8: 4 | K8: 4 | L8: =IF(M8="Yes",SUM(H8,J8),"") -> 43 | M8: Yes | N8: Open
A9: 46040 | B9: =TEXT(A9,"ddd") -> Sun | C9: North Texas Saluki Club | D9: Celina | E9: TX | F9: 2026679804 | G9: All-breed | H9: 19 | I9: 18 | J9: 4 | K9: 4 | L9: =IF(M9="Yes",SUM(H9,J9),"") -> 23 | M9: Yes | N9: Open
A10: 46060 | B10: =TEXT(A10,"ddd") -> Sat | C10: Sunshine State Rhodesian Ridgeback Club | D10: High Springs | E10: FL | F10: 2026702925 | G10: All-breed | H10: 41 | I10: 41 | J10: 9 | K10: 9 | L10: =IF(M10="Yes",SUM(H10,J10),"") -> 50 | M10: Yes | N10: Open
A11: 46061 | B11: =TEXT(A11,"ddd") -> Sun | C11: Sunshine State Rhodesian Ridgeback Club | D11: High Springs | E11: FL | F11: 2026702926 | G11: All-breed | H11: 50 | I11: 50 | J11: 3 | K11: 3 | L11: =IF(M11="Yes",SUM(H11,J11),"") -> 53 | M11: Yes | N11: Open
A12: 46067 | B12: =TEXT(A12,"ddd") -> Sat | C12: Orange Coast Rhodesian Ridgeback Club | D12: Chino | E12: CA | F12: 2026281101 | G12: All-breed | H12: 24 | I12: 24 | J12: 4 | K12: 4 | L12: =IF(M12="Yes",SUM(H12,J12),"") -> 28 | M12: Yes | N12: Open
A13: 46068 | B13: =TEXT(A13,"ddd") -> Sun | C13: Orange Coast Rhodesian Ridgeback Club | D13: Chino | E13: CA | F13: 2026281102 | G13: All-breed | H13: 19 | I13: 19 | J13: 4 | K13: 4 | L13: =IF(M13="Yes",SUM(H13,J13),"") -> 23 | M13: Yes | N13: Open
... A24: 46089 | B24: =TEXT(A24,"ddd") -> Sun | C24: Evergreen Basenji Club | D24: Roy | E24: WA | F24: 2026184304 | G24: All-breed | H24: 32 | I24: 32 | J24: 4 | K24: 4 | L24: =IF(M24="Yes",SUM(H24,J24),"") -> 36 | M24: Yes | N24: Open
A25: 46102 | B25: =TEXT(A25,"ddd") -> Sat | C25: Greater Ocala-Gainesville Lure Coursing Association | D25: Brooksville | E25: FL | F25: 2026258603 | G25: All-breed | H25: 35 | I25: 35 | L25: =IF(M25="Yes",SUM(H25,J25),"") -> 35 | M25: Yes | N25: Open
A26: 46102 | B26: =TEXT(A26,"ddd") -> Sat | C26: Lobo Lure Coursing Club | D26: Santa Fe | E26: NM | F26: 2026250105 | G26: All-breed | H26: 13 | I26: 13 | J26: 5 | K26: 5 | L26: =IF(M26="Yes",SUM(H26,J26),"") -> 18 | M26: Yes | N26: Open
A27: 46103 | B27: =TEXT(A27,"ddd") -> Sun | C27: Greater Ocala-Gainesville Lure Coursing Association | D27: Brooksville | E27: FL | F27: 2026258604 | G27: All-breed | H27: 47 | I27: 43 | J27: 7 | K27: 7 | L27: =IF(M27="Yes",SUM(H27,J27),"") -> 54 | M27: Yes | N27: Open
A28: 46103 | B28: =TEXT(A28,"ddd") -> Sun | C28: Lobo Lure Coursing Club | D28: Santa Fe | E28: NM | F28: 2026250106 | G28: All-breed | H28: 11 | I28: 10 | J28: 3 | K28: 3 | L28: =IF(M28="Yes",SUM(H28,J28),"") -> 14 | M28: Yes | N28: Open
A29: 46109 | B29: =TEXT(A29,"ddd") -> Sat | C29: Sierra Slopes Ibizan Hounds | D29: Elverta | E29: CA | F29: 2026268703 | G29: All-breed | H29: 43 | I29: 43 | J29: 7 | K29: 7 | L29: =IF(M29="Yes",SUM(H29,J29),"") -> 50 | M29: Yes | N29: Open
A30: 46109 | B30: =TEXT(A30,"ddd") -> Sat | C30: Northwest Rhodesian Ridgeback Club | D30: Ethel | E30: WA | F30: 2026686303 | G30: All-breed | H30: 37 | I30: 37 | J30: 5 | K30: 4 | L30: =IF(M30="Yes",SUM(H30,J30),"") -> 42 | M30: Yes | N30: Open
A31: 46109 | B31: =TEXT(A31,"ddd") -> Sat | C31: Afghan Hound Club of Austin | D31: Florence | E31: TX | F31: 2026169402 | G31: All-breed | H31: 52 | I31: 51 | J31: 9 | K31: 8 | L31: =IF(M31="Yes",SUM(H31,J31),"") -> 61 | M31: Yes | N31: Open
A32: 46109 | B32: =TEXT(A32,"ddd") -> Sat | C32: Sunshine State Rhodesian Ridgeback Club | D32: Weirsdale | E32: FL | F32: 2026702927 | G32: All-breed | H32: 39 | I32: 38 | J32: 4 | K32: 4 | L32: =IF(M32="Yes",SUM(H32,J32),"") -> 43 | M32: Yes | N32: Open
A33: 46109 | B33: =TEXT(A33,"ddd") -> Sat | C33: Midwest Borzoi Club | D33: Lima | E33: OH | F33: 2026058402 | G33: All-breed | H33: 64 | I33: 64 | J33: 15 | K33: 14 | L33: =IF(M33="Yes",SUM(H33,J33),"") -> 79 | M33: Yes | N33: Open
A34: 46110 | B34: =TEXT(A34,"ddd") -> Sun | C34: Sunshine State Rhodesian Ridgeback Club | D34: Weirsdale | E34: FL | F34: 2026702928 | G34: All-breed | H34: 38 | I34: 36 | J34: 0 | K34: 0 | L34: =IF(M34="Yes",SUM(H34,J34),"") -> 38 | M34: Yes | N34: Open
A35: 46110 | B35: =TEXT(A35,"ddd") -> Sun | C35: Northwest Rhodesian Ridgeback Club | D35: Ethel | E35: WA | F35: 2026686304 | G35: All-breed | H35: 33 | I35: 32 | J35: 3 | K35: 3 | L35: =IF(M35="Yes",SUM(H35,J35),"") -> 36 | M35: Yes | N35: Open
A36: 46110 | B36: =TEXT(A36,"ddd") -> Sun | C36: Afghan Hound Club of Austin | D36: Florence | E36: TX | F36: 2026169401 | G36: All-breed | H36: 52 | I36: 47 | J36: 4 | K36: 3 | L36: =IF(M36="Yes",SUM(H36,J36),"") -> 56 | M36: Yes | N36: Open
A37: 46110 | B37: =TEXT(A37,"ddd") -> Sun | C37: Midwest Borzoi Club | D37: Lima | E37: OH | F37: 2026058403 | G37: All-breed | H37: 67 | I37: 64 | J37: 14 | K37: 14 | L37: =IF(M37="Yes",SUM(H37,J37),"") -> 81 | M37: Yes | N37: Open
... A39: 46116 | B39: =TEXT(A39,"ddd") -> Sat | C39: Irish Wolfhound Association of the Garden State | D39: Somerset | E39: NJ | F39: 2026283907 | G39: All-breed | H39: 18 | I39: 18 | J39: 8 | K39: 8 | L39: =IF(M39="Yes",SUM(H39,J39),"") -> 26 | M39: Yes | N39: Open
A40: 46116 | B40: =TEXT(A40,"ddd") -> Sat | C40: Iowa Coursing Association | D40: Des Moines | E40: IA | F40: 2026259701 | G40: All-breed | H40: 36 | I40: 36 | L40: =IF(M40="Yes",SUM(H40,J40),"") -> 36 | M40: Yes | N40: Open
A41: 46117 | B41: =TEXT(A41,"ddd") -> Sun | C41: Irish Wolfhound Association of the Garden State | D41: Somerset | E41: NJ | F41: 2026283908 | G41: All-breed | H41: 13 | I41: 13 | J41: 2 | K41: 2 | L41: =IF(M41="Yes",SUM(H41,J41),"") -> 15 | M41: Yes | N41: Open
A42: 46121 | B42: =TEXT(A42,"ddd") -> Thu | C42: Orange Coast Rhodesian Ridgeback Club | D42: Chino | E42: CA | F42: 2026281106 | G42: All-breed | H42: 36 | I42: 35 | L42: =IF(M42="Yes",SUM(H42,J42),"") -> 36 | M42: Yes | N42: Open
A43: 46123 | B43: =TEXT(A43,"ddd") -> Sat | C43: Greater Valley Forge Rhodesian Ridgeback Club, Inc. | D43: Somerset | E43: NJ | F43: 2026288901 | G43: All-breed | H43: 27 | I43: 26 | J43: 9 | K43: 9 | L43: =IF(M43="Yes",SUM(H43,J43),"") -> 36 | M43: Yes | N43: Open
A44: 46123 | B44: =TEXT(A44,"ddd") -> Sat | C44: OKI Gazehound Association of Ohio | D44: Fairborn | E44: OH | F44: 2026265201 | G44: All-breed | H44: 52 | I44: 51 | J44: 13 | K44: 13 | L44: =IF(M44="Yes",SUM(H44,J44),"") -> 65 | M44: Yes | N44: Open
A45: 46123 | B45: =TEXT(A45,"ddd") -> Sat | C45: Trinity Valley Rhodesian Ridgeback Club of Texas | D45: Ponder | E45: TX | F45: 2026295406 | G45: All-breed | H45: 37 | I45: 37 | J45: 9 | K45: 9 | L45: =IF(M45="Yes",SUM(H45,J45),"") -> 46 | M45: Yes | N45: Open
A46: 46124 | B46: =TEXT(A46,"ddd") -> Sun | C46: Greater Valley Forge Rhodesian Ridgeback Club, Inc. | D46: Somerset | E46: NJ | F46: 2026288902 | G46: All-breed | H46: 31 | I46: 30 | J46: 6 | K46: 6 | L46: =IF(M46="Yes",SUM(H46,J46),"") -> 37 | M46: Yes | N46: Open
A47: 46124 | B47: =TEXT(A47,"ddd") -> Sun | C47: OKI Gazehound Association of Ohio | D47: Fairborn | E47: OH | F47: 2026265202 | G47: All-breed | H47: 46 | I47: 44 | J47: 3 | K47: 3 | L47: =IF(M47="Yes",SUM(H47,J47),"") -> 49 | M47: Yes | N47: Open
A48: 46124 | B48: =TEXT(A48,"ddd") -> Sun | C48: American Whippet Club, Inc. | D48: Pasco | E48: WA | F48: 2026074707 | G48: Whippet specialty | H48: 77 | I48: 74 | L48: =IF(M48="Yes",SUM(H48,J48),"") -> 77 | M48: Yes | N48: Open
A49: 46124 | B49: =TEXT(A49,"ddd") -> Sun | C49: Trinity Valley Rhodesian Ridgeback Club of Texas | D49: Ponder | E49: TX | F49: 2026295407 | G49: All-breed | H49: 40 | I49: 40 | J49: 3 | K49: 3 | L49: =IF(M49="Yes",SUM(H49,J49),"") -> 43 | M49: Yes | N49: Open
A50: 46130 | B50: =TEXT(A50,"ddd") -> Sat | C50: Western Washington Hound Association | D50: Ethel | E50: WA | F50: 2026325804 | G50: All-breed | H50: 42 | I50: 40 | J50: 6 | K50: 6 | L50: =IF(M50="Yes",SUM(H50,J50),"") -> 48 | M50: Yes | N50: Open
A51: 46130 | B51: =TEXT(A51,"ddd") -> Sat | C51: Utah Sighthound Racing and Coursing Club | D51: South Jordan | E51: UT | F51: 2026271203 | G51: All-breed | H51: 15 | I51: 15 | J51: 1 | K51: 1 | L51: =IF(M51="Yes",SUM(H51,J51),"") -> 16 | M51: Yes | N51: Open
...

Sheet Summary
A1: AKC lure coursing entries, January 1 to October 9, 2026
A2: Source: AKC Event Search, event type Lure Coursing Tests & Trials (LC), all states. Collected October 9, 2026.
A4: Events listed | B4: =COUNTA(Trials!$F$2:$F$149) -> 148
A5: Events with results posted | B5: =COUNTIF(Trials!$M$2:$M$149,"Yes") -> 123
A6: Events without results posted yet | B6: =COUNTIF(Trials!$M$2:$M$149,"No") -> 25
A7: LC Trial entries | B7: =SUM(Trials!$H$2:$H$149) -> 3938
A8: LC Trial competitors | B8: =SUM(Trials!$I$2:$I$149) -> 3828
A9: LC Test entries (JC/QC) | B9: =SUM(Trials!$J$2:$J$149) -> 622
A10: LC Test competitors | B10: =SUM(Trials!$K$2:$K$149) -> 606
A11: Total entries (trial + test) | B11: =SUM(Trials!$L$2:$L$149) -> 4560
A12: Events that held an LC Trial | B12: =COUNT(Trials!$H$2:$H$149) -> 121
A13: Average LC Trial entries per trial | B13: =B7/B12 -> 32.545455
A14: Largest LC Trial entry | B14: =MAX(Trials!$H$2:$H$149) -> 77
A15: Smallest LC Trial entry | B15: =MIN(Trials!$H$2:$H$149) -> 6
A17: By month
A18: Month | B18: Events | C18: With results | D18: LC Trial entries | E18: LC Test entries | F18: Total entries | G18: Avg trial entries
A19: 46023 | B19: =COUNTIFS(Trials!$A$2:$A$149,">="&DATE(2026,1,1),Trials!$A$2:$A$149,"<"&DATE(2026,2,1)) -> 8 | C19: =COUNTIFS(Trials!$A$2:$A$149,">="&DATE(2026,1,1),Trials!$A$2:$A$149,"<"&DATE(2026,2,1),Trials!$M$2:$M$149,"Yes") -> 8 | D19: =SUMIFS(Trials!$H$2:$H$149,Trials!$A$2:$A$149,">="&DATE(2026,1,1),Trials!$A$2:$A$149,"<"&DATE(2026,2,1)) -> 319 | E19: =SUMIFS(Trials!$J$2:$J$149,Trials!$A$2:$A$149,">="&DATE(2026,1,1),Trials!$A$2:$A$149,"<"&DATE(2026,2,1)) -> 51 | F19: =D19+E19 -> 370 | G19: =IF(COUNTIFS(Trials!$A$2:$A$149,">="&DATE(2026,1,1),Trials!$A$2:$A$149,"<"&DATE(2026,2,1),Trials!$H$2:$H$149,">=0")=0,"",D19/COUNTIFS(Trials!$A$2:$A$149,">="&DATE(2026,1,1),Trials!$A$2:$A$149,"<"&DATE(2026,2,1),Trials!$H$2:$H$149,">=0")) -> 39.875
A20: 46054 | B20: =COUNTIFS(Trials!$A$2:$A$149,">="&DATE(2026,2,1),Trials!$A$2:$A$149,"<"&DATE(2026,3,1)) -> 9 | C20: =COUNTIFS(Trials!$A$2:$A$149,">="&DATE(2026,2,1),Trials!$A$2:$A$149,"<"&DATE(2026,3,1),Trials!$M$2:$M$149,"Yes") -> 9 | D20: =SUMIFS(Trials!$H$2:$H$149,Trials!$A$2:$A$149,">="&DATE(2026,2,1),Trials!$A$2:$A$149,"<"&DATE(2026,3,1)) -> 372 | E20: =SUMIFS(Trials!$J$2:$J$149,Trials!$A$2:$A$149,">="&DATE(2026,2,1),Trials!$A$2:$A$149,"<"&DATE(2026,3,1)) -> 46 | F20: =D20+E20 -> 418 | G20: =IF(COUNTIFS(Trials!$A$2:$A$149,">="&DATE(2026,2,1),Trials!$A$2:$A$149,"<"&DATE(2026,3,1),Trials!$H$2:$H$149,">=0")=0,"",D20/COUNTIFS(Trials!$A$2:$A$149,">="&DATE(2026,2,1),Trials!$A$2:$A$149,"<"&DATE(2026,3,1),Trials!$H$2:$H$149,">=0")) -> 41.333333
A21: 46082 | B21: =COUNTIFS(Trials!$A$2:$A$149,">="&DATE(2026,3,1),Trials!$A$2:$A$149,"<"&DATE(2026,4,1)) -> 20 | C21: =COUNTIFS(Trials!$A$2:$A$149,">="&DATE(2026,3,1),Trials!$A$2:$A$149,"<"&DATE(2026,4,1),Trials!$M$2:$M$149,"Yes") -> 20 | D21: =SUMIFS(Trials!$H$2:$H$149,Trials!$A$2:$A$149,">="&DATE(2026,3,1),Trials!$A$2:$A$149,"<"&DATE(2026,4,1)) -> 784 | E21: =SUMIFS(Trials!$J$2:$J$149,Trials!$A$2:$A$149,">="&DATE(2026,3,1),Trials!$A$2:$A$149,"<"&DATE(2026,4,1)) -> 126 | F21: =D21+E21 -> 910 | G21: =IF(COUNTIFS(Trials!$A$2:$A$149,">="&DATE(2026,3,1),Trials!$A$2:$A$149,"<"&DATE(2026,4,1),Trials!$H$2:$H$149,">=0")=0,"",D21/COUNTIFS(Trials!$A$2:$A$149,">="&DATE(2026,3,1),Trials!$A$2:$A$149,"<"&DATE(2026,4,1),Trials!$H$2:$H$149,">=0")) -> 39.2
A22: 46113 | B22: =COUNTIFS(Trials!$A$2:$A$149,">="&DATE(2026,4,1),Trials!$A$2:$A$149,"<"&DATE(2026,5,1)) -> 17 | C22: =COUNTIFS(Trials!$A$2:$A$149,">="&DATE(2026,4,1),Trials!$A$2:$A$149,"<"&DATE(2026,5,1),Trials!$M$2:$M$149,"Yes") -> 17 | D22: =SUMIFS(Trials!$H$2:$H$149,Trials!$A$2:$A$149,">="&DATE(2026,4,1),Trials!$A$2:$A$149,"<"&DATE(2026,5,1)) -> 556 | E22: =SUMIFS(Trials!$J$2:$J$149,Trials!$A$2:$A$149,">="&DATE(2026,4,1),Trials!$A$2:$A$149,"<"&DATE(2026,5,1)) -> 80 | F22: =D22+E22 -> 636 | G22: =IF(COUNTIFS(Trials!$A$2:$A$149,">="&DATE(2026,4,1),Trials!$A$2:$A$149,"<"&DATE(2026,5,1),Trials!$H$2:$H$149,">=0")=0,"",D22/COUNTIFS(Trials!$A$2:$A$149,">="&DATE(2026,4,1),Trials!$A$2:$A$149,"<"&DATE(2026,5,1),Trials!$H$2:$H$149,">=0")) -> 32.705882
A23: 46143 | B23: =COUNTIFS(Trials!$A$2:$A$149,">="&DATE(2026,5,1),Trials!$A$2:$A$149,"<"&DATE(2026,6,1)) -> 34 | C23: =COUNTIFS(Trials!$A$2:$A$149,">="&DATE(2026,5,1),Trials!$A$2:$A$149,"<"&DATE(2026,6,1),Trials!$M$2:$M$149,"Yes") -> 34 | D23: =SUMIFS(Trials!$H$2:$H$149,Trials!$A$2:$A$149,">="&DATE(2026,5,1),Trials!$A$2:$A$149,"<"&DATE(2026,6,1)) -> 878 | E23: =SUMIFS(Trials!$J$2:$J$149,Trials!$A$2:$A$149,">="&DATE(2026,5,1),Trials!$A$2:$A$149,"<"&DATE(2026,6,1)) -> 159 | F23: =D23+E23 -> 1037 | G23: =IF(COUNTIFS(Trials!$A$2:$A$149,">="&DATE(2026,5,1),Trials!$A$2:$A$149,"<"&DATE(2026,6,1),Trials!$H$2:$H$149,">=0")=0,"",D23/COUNTIFS(Trials!$A$2:$A$149,">="&DATE(2026,5,1),Trials!$A$2:$A$149,"<"&DATE(2026,6,1),Trials!$H$2:$H$149,">=0")) -> 26.606061
A24: 46174 | B24: =COUNTIFS(Trials!$A$2:$A$149,">="&DATE(2026,6,1),Trials!$A$2:$A$149,"<"&DATE(2026,7,1)) -> 20 | C24: =COUNTIFS(Trials!$A$2:$A$149,">="&DATE(2026,6,1),Trials!$A$2:$A$149,"<"&DATE(2026,7,1),Trials!$M$2:$M$149,"Yes") -> 20 | D24: =SUMIFS(Trials!$H$2:$H$149,Trials!$A$2:$A$149,">="&DATE(2026,6,1),Trials!$A$2:$A$149,"<"&DATE(2026,7,1)) -> 588 | E24: =SUMIFS(Trials!$J$2:$J$149,Trials!$A$2:$A$149,">="&DATE(2026,6,1),Trials!$A$2:$A$149,"<"&DATE(2026,7,1)) -> 101 | F24: =D24+E24 -> 689 | G24: =IF(COUNTIFS(Trials!$A$2:$A$149,">="&DATE(2026,6,1),Trials!$A$2:$A$149,"<"&DATE(2026,7,1),Trials!$H$2:$H$149,">=0")=0,"",D24/COUNTIFS(Trials!$A$2:$A$149,">="&DATE(2026,6,1),Trials!$A$2:$A$149,"<"&DATE(2026,7,1),Trials!$H$2:$H$149,">=0")) -> 30.947368
A25: 46204 | B25: =COUNTIFS(Trials!$A$2:$A$149,">="&DATE(2026,7,1),Trials!$A$2:$A$149,"<"&DATE(2026,8,1)) -> 8 | C25: =COUNTIFS(Trials!$A$2:$A$149,">="&DATE(2026,7,1),Trials!$A$2:$A$149,"<"&DATE(2026,8,1),Trials!$M$2:$M$149,"Yes") -> 8 | D25: =SUMIFS(Trials!$H$2:$H$149,Trials!$A$2:$A$149,">="&DATE(2026,7,1),Trials!$A$2:$A$149,"<"&DATE(2026,8,1)) -> 189 | E25: =SUMIFS(Trials!$J$2:$J$149,Trials!$A$2:$A$149,">="&DATE(2026,7,1),Trials!$A$2:$A$149,"<"&DATE(2026,8,1)) -> 33 | F25: =D25+E25 -> 222 | G25: =IF(COUNTIFS(Trials!$A$2:$A$149,">="&DATE(2026,7,1),Trials!$A$2:$A$149,"<"&DATE(2026,8,1),Trials!$H$2:$H$149,">=0")=0,"",D25/COUNTIFS(Trials!$A$2:$A$149,">="&DATE(2026,7,1),Trials!$A$2:$A$149,"<"&DATE(2026,8,1),Trials!$H$2:$H$149,">=0")) -> 23.625
A26: 46235 | B26: =COUNTIFS(Trials!$A$2:$A$149,">="&DATE(2026,8,1),Trials!$A$2:$A$149,"<"&DATE(2026,9,1)) -> 4 | C26: =COUNTIFS(Trials!$A$2:$A$149,">="&DATE(2026,8,1),Trials!$A$2:$A$149,"<"&DATE(2026,9,1),Trials!$M$2:$M$149,"Yes") -> 4 | D26: =SUMIFS(Trials!$H$2:$H$149,Trials!$A$2:$A$149,">="&DATE(2026,8,1),Trials!$A$2:$A$149,"<"&DATE(2026,9,1)) -> 115 | E26: =SUMIFS(Trials!$J$2:$J$149,Trials!$A$2:$A$149,">="&DATE(2026,8,1),Trials!$A$2:$A$149,"<"&DATE(2026,9,1)) -> 20 | F26: =D26+E26 -> 135 | G26: =IF(COUNTIFS(Trials!$A$2:$A$149,">="&DATE(2026,8,1),Trials!$A$2:$A$149,"<"&DATE(2026,9,1),Trials!$H$2:$H$149,">=0")=0,"",D26/COUNTIFS(Trials!$A$2:$A$149,">="&DATE(2026,8,1),Trials!$A$2:$A$149,"<"&DATE(2026,9,1),Trials!$H$2:$H$149,">=0")) -> 28.75
A27: 46266 | B27: =COUNTIFS(Trials!$A$2:$A$149,">="&DATE(2026,9,1),Trials!$A$2:$A$149,"<"&DATE(2026,10,1)) -> 17 | C27: =COUNTIFS(Trials!$A$2:$A$149,">="&DATE(2026,9,1),Trials!$A$2:$A$149,"<"&DATE(2026,10,1),Trials!$M$2:$M$149,"Yes") -> 3 | D27: =SUMIFS(Trials!$H$2:$H$149,Trials!$A$2:$A$149,">="&DATE(2026,9,1),Trials!$A$2:$A$149,"<"&DATE(2026,10,1)) -> 137 | E27: =SUMIFS(Trials!$J$2:$J$149,Trials!$A$2:$A$149,">="&DATE(2026,9,1),Trials!$A$2:$A$149,"<"&DATE(2026,10,1)) -> 6 | F27: =D27+E27 -> 143 | G27: =IF(COUNTIFS(Trials!$A$2:$A$149,">="&DATE(2026,9,1),Trials!$A$2:$A$149,"<"&DATE(2026,10,1),Trials!$H$2:$H$149,">=0")=0,"",D27/COUNTIFS(Trials!$A$2:$A$149,">="&DATE(2026,9,1),Trials!$A$2:$A$149,"<"&DATE(2026,10,1),Trials!$H$2:$H$149,">=0")) -> 45.666667
A28: 46296 | B28: =COUNTIFS(Trials!$A$2:$A$149,">="&DATE(2026,10,1),Trials!$A$2:$A$149,"<"&DATE(2026,11,1)) -> 11 | C28: =COUNTIFS(Trials!$A$2:$A$149,">="&DATE(2026,10,1),Trials!$A$2:$A$149,"<"&DATE(2026,11,1),Trials!$M$2:$M$149,"Yes") -> 0 | D28: =SUMIFS(Trials!$H$2:$H$149,Trials!$A$2:$A$149,">="&DATE(2026,10,1),Trials!$A$2:$A$149,"<"&DATE(2026,11,1)) -> 0 | E28: =SUMIFS(Trials!$J$2:$J$149,Trials!$A$2:$A$149,">="&DATE(2026,10,1),Trials!$A$2:$A$149,"<"&DATE(2026,11,1)) -> 0 | F28: =D28+E28 -> 0 | G28: =IF(COUNTIFS(Trials!$A$2:$A$149,">="&DATE(2026,10,1),Trials!$A$2:$A$149,"<"&DATE(2026,11,1),Trials!$H$2:$H$149,">=0")=0,"",D28/COUNTIFS(Trials!$A$2:$A$149,">="&DATE(2026,10,1),Trials!$A$2:$A$149,"<"&DATE(2026,11,1),Trials!$H$2:$H$149,">=0"))
A29: Total | B29: =SUM(B19:B28) -> 148 | C29: =SUM(C19:C28) -> 123 | D29: =SUM(D19:D28) -> 3938 | E29: =SUM(E19:E28) -> 622 | F29: =SUM(F19:F28) -> 4560
A32: By state
A33: State | B33: Events | C33: With results | D33: LC Trial entries | E33: LC Test entries | F33: Total entries | G33: Avg trial entries
A34: AK | B34: =COUNTIF(Trials!$E$2:$E$149,A34) -> 7 | C34: =COUNTIFS(Trials!$E$2:$E$149,A34,Trials!$M$2:$M$149,"Yes") -> 5 | D34: =SUMIF(Trials!$E$2:$E$149,A34,Trials!$H$2:$H$149) -> 41 | E34: =SUMIF(Trials!$E$2:$E$149,A34,Trials!$J$2:$J$149) -> 6 | F34: =D34+E34 -> 47 | G34: =IF(COUNTIFS(Trials!$E$2:$E$149,A34,Trials!$H$2:$H$149,">=0")=0,"",D34/COUNTIFS(Trials!$E$2:$E$149,A34,Trials!$H$2:$H$149,">=0")) -> 8.2
A35: AL | B35: =COUNTIF(Trials!$E$2:$E$149,A35) -> 2 | C35: =COUNTIFS(Trials!$E$2:$E$149,A35,Trials!$M$2:$M$149,"Yes") -> 2 | D35: =SUMIF(Trials!$E$2:$E$149,A35,Trials!$H$2:$H$149) -> 32 | E35: =SUMIF(Trials!$E$2:$E$149,A35,Trials!$J$2:$J$149) -> 16 | F35: =D35+E35 -> 48 | G35: =IF(COUNTIFS(Trials!$E$2:$E$149,A35,Trials!$H$2:$H$149,">=0")=0,"",D35/COUNTIFS(Trials!$E$2:$E$149,A35,Trials!$H$2:$H$149,">=0")) -> 16
A36: AZ | B36: =COUNTIF(Trials!$E$2:$E$149,A36) -> 8 | C36: =COUNTIFS(Trials!$E$2:$E$149,A36,Trials!$M$2:$M$149,"Yes") -> 8 | D36: =SUMIF(Trials!$E$2:$E$149,A36,Trials!$H$2:$H$149) -> 281 | E36: =SUMIF(Trials!$E$2:$E$149,A36,Trials!$J$2:$J$149) -> 44 | F36: =D36+E36 -> 325 | G36: =IF(COUNTIFS(Trials!$E$2:$E$149,A36,Trials!$H$2:$H$149,">=0")=0,"",D36/COUNTIFS(Trials!$E$2:$E$149,A36,Trials!$H$2:$H$149,">=0")) -> 35.125
A37: CA | B37: =COUNTIF(Trials!$E$2:$E$149,A37) -> 14 | C37: =COUNTIFS(Trials!$E$2:$E$149,A37,Trials!$M$2:$M$149,"Yes") -> 10 | D37: =SUMIF(Trials!$E$2:$E$149,A37,Trials!$H$2:$H$149) -> 372 | E37: =SUMIF(Trials!$E$2:$E$149,A37,Trials!$J$2:$J$149) -> 59 | F37: =D37+E37 -> 431 | G37: =IF(COUNTIFS(Trials!$E$2:$E$149,A37,Trials!$H$2:$H$149,">=0")=0,"",D37/COUNTIFS(Trials!$E$2:$E$149,A37,Trials!$H$2:$H$149,">=0")) -> 37.2
A38: CO | B38: =COUNTIF(Trials!$E$2:$E$149,A38) -> 3 | C38: =COUNTIFS(Trials!$E$2:$E$149,A38,Trials!$M$2:$M$149,"Yes") -> 3 | D38: =SUMIF(Trials!$E$2:$E$149,A38,Trials!$H$2:$H$149) -> 66 | E38: =SUMIF(Trials!$E$2:$E$149,A38,Trials!$J$2:$J$149) -> 15 | F38: =D38+E38 -> 81 | G38: =IF(COUNTIFS(Trials!$E$2:$E$149,A38,Trials!$H$2:$H$149,">=0")=0,"",D38/COUNTIFS(Trials!$E$2:$E$149,A38,Trials!$H$2:$H$149,">=0")) -> 22
A39: CT | B39: =COUNTIF(Trials!$E$2:$E$149,A39) -> 2 | C39: =COUNTIFS(Trials!$E$2:$E$149,A39,Trials!$M$2:$M$149,"Yes") -> 2 | D39: =SUMIF(Trials!$E$2:$E$149,A39,Trials!$H$2:$H$149) -> 93 | E39: =SUMIF(Trials!$E$2:$E$149,A39,Trials!$J$2:$J$149) -> 16 | F39: =D39+E39 -> 109 | G39: =IF(COUNTIFS(Trials!$E$2:$E$149,A39,Trials!$H$2:$H$149,">=0")=0,"",D39/COUNTIFS(Trials!$E$2:$E$149,A39,Trials!$H$2:$H$149,">=0")) -> 46.5
A40: FL | B40: =COUNTIF(Trials!$E$2:$E$149,A40) -> 10 | C40: =COUNTIFS(Trials!$E$2:$E$149,A40,Trials!$M$2:$M$149,"Yes") -> 10 | D40: =SUMIF(Trials!$E$2:$E$149,A40,Trials!$H$2:$H$149) -> 420 | E40: =SUMIF(Trials!$E$2:$E$149,A40,Trials!$J$2:$J$149) -> 42 | F40: =D40+E40 -> 462 | G40: =IF(COUNTIFS(Trials!$E$2:$E$149,A40,Trials!$H$2:$H$149,">=0")=0,"",D40/COUNTIFS(Trials!$E$2:$E$149,A40,Trials!$H$2:$H$149,">=0")) -> 42
A41: GA | B41: =COUNTIF(Trials!$E$2:$E$149,A41) -> 2 | C41: =COUNTIFS(Trials!$E$2:$E$149,A41,Trials!$M$2:$M$149,"Yes") -> 0 | D41: =SUMIF(Trials!$E$2:$E$149,A41,Trials!$H$2:$H$149) -> 0 | E41: =SUMIF(Trials!$E$2:$E$149,A41,Trials!$J$2:$J$149) -> 0 | F41: =D41+E41 -> 0 | G41: =IF(COUNTIFS(Trials!$E$2:$E$149,A41,Trials!$H$2:$H$149,">=0")=0,"",D41/COUNTIFS(Trials!$E$2:$E$149,A41,Trials!$H$2:$H$149,">=0"))
A42: IA | B42: =COUNTIF(Trials!$E$2:$E$149,A42) -> 3 | C42: =COUNTIFS(Trials!$E$2:$E$149,A42,Trials!$M$2:$M$149,"Yes") -> 3 | D42: =SUMIF(Trials!$E$2:$E$149,A42,Trials!$H$2:$H$149) -> 120 | E42: =SUMIF(Trials!$E$2:$E$149,A42,Trials!$J$2:$J$149) -> 1 | F42: =D42+E42 -> 121 | G42: =IF(COUNTIFS(Trials!$E$2:$E$149,A42,Trials!$H$2:$H$149,">=0")=0,"",D42/COUNTIFS(Trials!$E$2:$E$149,A42,Trials!$H$2:$H$149,">=0")) -> 40
A43: IL | B43: =COUNTIF(Trials!$E$2:$E$149,A43) -> 1 | C43: =COUNTIFS(Trials!$E$2:$E$149,A43,Trials!$M$2:$M$149,"Yes") -> 0 | D43: =SUMIF(Trials!$E$2:$E$149,A43,Trials!$H$2:$H$149) -> 0 | E43: =SUMIF(Trials!$E$2:$E$149,A43,Trials!$J$2:$J$149) -> 0 | F43: =D43+E43 -> 0 | G43: =IF(COUNTIFS(Trials!$E$2:$E$149,A43,Trials!$H$2:$H$149,">=0")=0,"",D43/COUNTIFS(Trials!$E$2:$E$149,A43,Trials!$H$2:$H$149,">=0"))
A44: MI | B44: =COUNTIF(Trials!$E$2:$E$149,A44) -> 8 | C44: =COUNTIFS(Trials!$E$2:$E$149,A44,Trials!$M$2:$M$149,"Yes") -> 8 | D44: =SUMIF(Trials!$E$2:$E$149,A44,Trials!$H$2:$H$149) -> 331 | E44: =SUMIF(Trials!$E$2:$E$149,A44,Trials!$J$2:$J$149) -> 39 | F44: =D44+E44 -> 370 | G44: =IF(COUNTIFS(Trials!$E$2:$E$149,A44,Trials!$H$2:$H$149,">=0")=0,"",D44/COUNTIFS(Trials!$E$2:$E$149,A44,Trials!$H$2:$H$149,">=0")) -> 47.285714
...

Sheet Trial ranking
A1: Trials ranked by LC Trial entries
A2: Events with results posted that held a trial. Tied trials share a rank.
A4: Rank | B4: Date | C4: Club | D4: City | E4: State | F4: LC Trial entries | G4: LC Trial competitors | H4: LC Test entries
A5: =RANK(F5,$F$5:$F$125) -> 1 | B5: =Trials!A48 -> 46124 | C5: =Trials!C48 -> American Whippet Club, Inc. | D5: =Trials!D48 -> Pasco | E5: =Trials!E48 -> WA | F5: =Trials!H48 -> 77 | G5: =Trials!I48 -> 74 | H5: =IF(Trials!J48="","",Trials!J48)
A6: =RANK(F6,$F$5:$F$125) -> 1 | B6: =Trials!A109 -> 46201 | C6: =Trials!C109 -> Michigan Gazehound Association | D6: =Trials!D109 -> Williamston | E6: =Trials!E109 -> MI | F6: =Trials!H109 -> 77 | G6: =Trials!I109 -> 61 | H6: =IF(Trials!J109="","",Trials!J109) -> 2
A7: =RANK(F7,$F$5:$F$125) -> 3 | B7: =Trials!A73 -> 46158 | C7: =Trials!C73 -> Trinity Valley Rhodesian Ridgeback Club of Texas | D7: =Trials!D73 -> McKinney | E7: =Trials!E73 -> TX | F7: =Trials!H73 -> 73 | G7: =Trials!I73 -> 73 | H7: =IF(Trials!J73="","",Trials!J73) -> 4
A8: =RANK(F8,$F$5:$F$125) -> 4 | B8: =Trials!A106 -> 46200 | C8: =Trials!C106 -> Michigan Gazehound Association | D8: =Trials!D106 -> Williamston | E8: =Trials!E106 -> MI | F8: =Trials!H106 -> 72 | G8: =Trials!I106 -> 69 | H8: =IF(Trials!J106="","",Trials!J106) -> 6
A9: =RANK(F9,$F$5:$F$125) -> 5 | B9: =Trials!A37 -> 46110 | C9: =Trials!C37 -> Midwest Borzoi Club | D9: =Trials!D37 -> Lima | E9: =Trials!E37 -> OH | F9: =Trials!H37 -> 67 | G9: =Trials!I37 -> 64 | H9: =IF(Trials!J37="","",Trials!J37) -> 14
A10: =RANK(F10,$F$5:$F$125) -> 6 | B10: =Trials!A33 -> 46109 | C10: =Trials!C33 -> Midwest Borzoi Club | D10: =Trials!D33 -> Lima | E10: =Trials!E33 -> OH | F10: =Trials!H33 -> 64 | G10: =Trials!I33 -> 64 | H10: =IF(Trials!J33="","",Trials!J33) -> 15
A11: =RANK(F11,$F$5:$F$125) -> 7 | B11: =Trials!A80 -> 46159 | C11: =Trials!C80 -> Trinity Valley Rhodesian Ridgeback Club of Texas | D11: =Trials!D80 -> McKinney | E11: =Trials!E80 -> TX | F11: =Trials!H80 -> 63 | G11: =Trials!I80 -> 63 | H11: =IF(Trials!J80="","",Trials!J80) -> 1
A12: =RANK(F12,$F$5:$F$125) -> 8 | B12: =Trials!A95 -> 46180 | C12: =Trials!C95 -> Michigan Gazehound Association | D12: =Trials!D95 -> Bellevue | E12: =Trials!E95 -> MI | F12: =Trials!H95 -> 62 | G12: =Trials!I95 -> 56 | H12: =IF(Trials!J95="","",Trials!J95) -> 4
A13: =RANK(F13,$F$5:$F$125) -> 9 | B13: =Trials!A5 -> 46033 | C13: =Trials!C5 -> Northern California Whippet Fanciers Association | D13: =Trials!D5 -> Elverta | E13: =Trials!E5 -> CA | F13: =Trials!H5 -> 61 | G13: =Trials!I5 -> 61 | H13: =IF(Trials!J5="","",Trials!J5) -> 8
A14: =RANK(F14,$F$5:$F$125) -> 10 | B14: =Trials!A4 -> 46032 | C14: =Trials!C4 -> Northern California Whippet Fanciers Association | D14: =Trials!D4 -> Elverta | E14: =Trials!E4 -> CA | F14: =Trials!H4 -> 59 | G14: =Trials!I4 -> 59 | H14: =IF(Trials!J4="","",Trials!J4) -> 14
A15: =RANK(F15,$F$5:$F$125) -> 11 | B15: =Trials!A123 -> 46271 | C15: =Trials!C123 -> Gazehound Association of the Smoky Mountains | D15: =Trials!D123 -> Limestone | E15: =Trials!E123 -> TN | F15: =Trials!H123 -> 56 | G15: =Trials!I123 -> 56 | H15: =IF(Trials!J123="","",Trials!J123) -> 3
A16: =RANK(F16,$F$5:$F$125) -> 12 | B16: =Trials!A15 -> 46074 | C16: =Trials!C15 -> Desert Fun Bunch Sighthound Club | D16: =Trials!D15 -> Tonopah | E16: =Trials!E15 -> AZ | F16: =Trials!H15 -> 54 | G16: =Trials!I15 -> 54 | H16: =IF(Trials!J15="","",Trials!J15) -> 8
A17: =RANK(F17,$F$5:$F$125) -> 12 | B17: =Trials!A71 -> 46158 | C17: =Trials!C71 -> Gazehounds of New England Lure Coursing Club | D17: =Trials!D71 -> Waterford | E17: =Trials!E71 -> CT | F17: =Trials!H71 -> 54 | G17: =Trials!I71 -> 51 | H17: =IF(Trials!J71="","",Trials!J71) -> 9
A18: =RANK(F18,$F$5:$F$125) -> 14 | B18: =Trials!A90 -> 46179 | C18: =Trials!C90 -> Michigan Gazehound Association | D18: =Trials!D90 -> Bellevue | E18: =Trials!E90 -> MI | F18: =Trials!H90 -> 53 | G18: =Trials!I90 -> 50 | H18: =IF(Trials!J90="","",Trials!J90) -> 16
A19: =RANK(F19,$F$5:$F$125) -> 15 | B19: =Trials!A14 -> 46074 | C19: =Trials!C14 -> Greater Ocala-Gainesville Lure Coursing Association | D19: =Trials!D14 -> Brooksville | E19: =Trials!E14 -> FL | F19: =Trials!H14 -> 52 | G19: =Trials!I14 -> 51 | H19: =IF(Trials!J14="","",Trials!J14) -> 4
A20: =RANK(F20,$F$5:$F$125) -> 15 | B20: =Trials!A31 -> 46109 | C20: =Trials!C31 -> Afghan Hound Club of Austin | D20: =Trials!D31 -> Florence | E20: =Trials!E31 -> TX | F20: =Trials!H31 -> 52 | G20: =Trials!I31 -> 51 | H20: =IF(Trials!J31="","",Trials!J31) -> 9
A21: =RANK(F21,$F$5:$F$125) -> 15 | B21: =Trials!A36 -> 46110 | C21: =Trials!C36 -> Afghan Hound Club of Austin | D21: =Trials!D36 -> Florence | E21: =Trials!E36 -> TX | F21: =Trials!H36 -> 52 | G21: =Trials!I36 -> 47 | H21: =IF(Trials!J36="","",Trials!J36) -> 4
A22: =RANK(F22,$F$5:$F$125) -> 15 | B22: =Trials!A44 -> 46123 | C22: =Trials!C44 -> OKI Gazehound Association of Ohio | D22: =Trials!D44 -> Fairborn | E22: =Trials!E44 -> OH | F22: =Trials!H44 -> 52 | G22: =Trials!I44 -> 51 | H22: =IF(Trials!J44="","",Trials!J44) -> 13
A23: =RANK(F23,$F$5:$F$125) -> 19 | B23: =Trials!A122 -> 46270 | C23: =Trials!C122 -> Gazehound Association of the Smoky Mountains | D23: =Trials!D122 -> Limestone | E23: =Trials!E122 -> TN | F23: =Trials!H122 -> 51 | G23: =Trials!I122 -> 50 | H23: =IF(Trials!J122="","",Trials!J122) -> 3
A24: =RANK(F24,$F$5:$F$125) -> 20 | B24: =Trials!A11 -> 46061 | C24: =Trials!C11 -> Sunshine State Rhodesian Ridgeback Club | D24: =Trials!D11 -> High Springs | E24: =Trials!E11 -> FL | F24: =Trials!H11 -> 50 | G24: =Trials!I11 -> 50 | H24: =IF(Trials!J11="","",Trials!J11) -> 3
A25: =RANK(F25,$F$5:$F$125) -> 21 | B25: =Trials!A21 -> 46088 | C25: =Trials!C21 -> Evergreen Basenji Club | D25: =Trials!D21 -> Roy | E25: =Trials!E21 -> WA | F25: =Trials!H21 -> 49 | G25: =Trials!I21 -> 49 | H25: =IF(Trials!J21="","",Trials!J21) -> 18
A26: =RANK(F26,$F$5:$F$125) -> 21 | B26: =Trials!A38 -> 46110 | C26: =Trials!C38 -> Sierra Slopes Ibizan Hounds | D26: =Trials!D38 -> Elverta | E26: =Trials!E38 -> CA | F26: =Trials!H38 -> 49 | G26: =Trials!I38 -> 48 | H26: =IF(Trials!J38="","",Trials!J38) -> 8
A27: =RANK(F27,$F$5:$F$125) -> 23 | B27: =Trials!A16 -> 46075 | C27: =Trials!C16 -> Desert Fun Bunch Sighthound Club | D27: =Trials!D16 -> Tonopah | E27: =Trials!E16 -> AZ | F27: =Trials!H16 -> 48 | G27: =Trials!I16 -> 48 | H27: =IF(Trials!J16="","",Trials!J16) -> 3
A28: =RANK(F28,$F$5:$F$125) -> 24 | B28: =Trials!A27 -> 46103 | C28: =Trials!C27 -> Greater Ocala-Gainesville Lure Coursing Association | D28: =Trials!D27 -> Brooksville | E28: =Trials!E27 -> FL | F28: =Trials!H27 -> 47 | G28: =Trials!I27 -> 43 | H28: =IF(Trials!J27="","",Trials!J27) -> 7
A29: =RANK(F29,$F$5:$F$125) -> 25 | B29: =Trials!A47 -> 46124 | C29: =Trials!C47 -> OKI Gazehound Association of Ohio | D29: =Trials!D47 -> Fairborn | E29: =Trials!E47 -> OH | F29: =Trials!H47 -> 46 | G29: =Trials!I47 -> 44 | H29: =IF(Trials!J47="","",Trials!J47) -> 3
A30: =RANK(F30,$F$5:$F$125) -> 26 | B30: =Trials!A64 -> 46152 | C30: =Trials!C64 -> Evergreen Basenji Club | D30: =Trials!D64 -> Roy | E30: =Trials!E64 -> WA | F30: =Trials!H64 -> 44 | G30: =Trials!I64 -> 44 | H30: =IF(Trials!J64="","",Trials!J64) -> 10
A31: =RANK(F31,$F$5:$F$125) -> 27 | B31: =Trials!A29 -> 46109 | C31: =Trials!C29 -> Sierra Slopes Ibizan Hounds | D31: =Trials!D29 -> Elverta | E31: =Trials!E29 -> CA | F31: =Trials!H29 -> 43 | G31: =Trials!I29 -> 43 | H31: =IF(Trials!J29="","",Trials!J29) -> 7
A32: =RANK(F32,$F$5:$F$125) -> 27 | B32: =Trials!A81 -> 46165 | C32: =Trials!C81 -> Iowa Coursing Association | D32: =Trials!D81 -> Cedar Falls | E32: =Trials!E81 -> IA | F32: =Trials!H81 -> 43 | G32: =Trials!I81 -> 35 | H32: =IF(Trials!J81="","",Trials!J81) -> 0
A33: =RANK(F33,$F$5:$F$125) -> 29 | B33: =Trials!A17 -> 46075 | C33: =Trials!C17 -> Greater Ocala-Gainesville Lure Coursing Association | D33: =Trials!D17 -> Brooksville | E33: =Trials!E17 -> FL | F33: =Trials!H17 -> 42 | G33: =Trials!I17 -> 42 | H33: =IF(Trials!J17="","",Trials!J17) -> 1
A34: =RANK(F34,$F$5:$F$125) -> 29 | B34: =Trials!A18 -> 46081 | C34: =Trials!C18 -> Alamo Area Whippet Club | D34: =Trials!D18 -> Angleton | E34: =Trials!E18 -> TX | F34: =Trials!H18 -> 42 | G34: =Trials!I18 -> 42 | H34: =IF(Trials!J18="","",Trials!J18) -> 10
A35: =RANK(F35,$F$5:$F$125) -> 29 | B35: =Trials!A50 -> 46130 | C35: =Trials!C50 -> Western Washington Hound Association | D35: =Trials!D50 -> Ethel | E35: =Trials!E50 -> WA | F35: =Trials!H50 -> 42 | G35: =Trials!I50 -> 40 | H35: =IF(Trials!J50="","",Trials!J50) -> 6
A36: =RANK(F36,$F$5:$F$125) -> 29 | B36: =Trials!A70 -> 46158 | C36: =Trials!C70 -> Sighthound Organization of Tidewater | D36: =Trials!D70 -> Dendron | E36: =Trials!E70 -> VA | F36: =Trials!H70 -> 42 | G36: =Trials!I70 -> 40 | H36: =IF(Trials!J70="","",Trials!J70) -> 9
A37: =RANK(F37,$F$5:$F$125) -> 33 | B37: =Trials!A3 -> 46026 | C37: =Trials!C3 -> Sunshine State Rhodesian Ridgeback Club | D37: =Trials!D3 -> Weirsdale | E37: =Trials!E3 -> FL | F37: =Trials!H3 -> 41 | G37: =Trials!I3 -> 37 | H37: =IF(Trials!J3="","",Trials!J3) -> 2
A38: =RANK(F38,$F$5:$F$125) -> 33 | B38: =Trials!A6 -> 46039 | C38: =Trials!C6 -> Desert Fun Bunch Sighthound Club | D38: =Trials!D6 -> Black Canyon City | E38: =Trials!E6 -> AZ | F38: =Trials!H6 -> 41 | G38: =Trials!I6 -> 41 | H38: =IF(Trials!J6="","",Trials!J6) -> 2
A39: =RANK(F39,$F$5:$F$125) -> 33 | B39: =Trials!A10 -> 46060 | C39: =Trials!C10 -> Sunshine State Rhodesian Ridgeback Club | D39: =Trials!D10 -> High Springs | E39: =Trials!E10 -> FL | F39: =Trials!H10 -> 41 | G39: =Trials!I10 -> 41 | H39: =IF(Trials!J10="","",Trials!J10) -> 9
A40: =RANK(F40,$F$5:$F$125) -> 33 | B40: =Trials!A84 -> 46166 | C40: =Trials!C84 -> Iowa Coursing Association | D40: =Trials!D84 -> Cedar Falls | E40: =Trials!E84 -> IA | F40: =Trials!H84 -> 41 | G40: =Trials!I84 -> 37 | H40: =IF(Trials!J84="","",Trials!J84) -> 1
A41: =RANK(F41,$F$5:$F$125) -> 37 | B41: =Trials!A49 -> 46124 | C41: =Trials!C49 -> Trinity Valley Rhodesian Ridgeback Club of Texas | D41: =Trials!D49 -> Ponder | E41: =Trials!E49 -> TX | F41: =Trials!H49 -> 40 | G41: =Trials!I49 -> 40 | H41: =IF(Trials!J49="","",Trials!J49) -> 3
...

Sheet Club ranking
A1: Clubs ranked by total LC Trial entries
A2: Totals across each club's trials with results posted, January 1 to October 9, 2026.
A4: Rank | B4: Club | C4: Trials held | D4: LC Trial entries | E4: Avg per trial | F4: Largest trial | G4: LC Test entries
A5: =RANK(D5,$D$5:$D$55) -> 1 | B5: Michigan Gazehound Association | C5: =COUNTIFS(Trials!$C$2:$C$149,B5,Trials!$H$2:$H$149,">=0") -> 4 | D5: =SUMIF(Trials!$C$2:$C$149,B5,Trials!$H$2:$H$149) -> 264 | E5: =D5/C5 -> 66 | F5: =SUMPRODUCT(MAX((Trials!$C$2:$C$149=B5)*Trials!$H$2:$H$149)) -> 77 | G5: =SUMIF(Trials!$C$2:$C$149,B5,Trials!$J$2:$J$149) -> 39
A6: =RANK(D6,$D$5:$D$55) -> 2 | B6: Sunshine State Rhodesian Ridgeback Club | C6: =COUNTIFS(Trials!$C$2:$C$149,B6,Trials!$H$2:$H$149,">=0") -> 6 | D6: =SUMIF(Trials!$C$2:$C$149,B6,Trials!$H$2:$H$149) -> 244 | E6: =D6/C6 -> 40.666667 | F6: =SUMPRODUCT(MAX((Trials!$C$2:$C$149=B6)*Trials!$H$2:$H$149)) -> 50 | G6: =SUMIF(Trials!$C$2:$C$149,B6,Trials!$J$2:$J$149) -> 30
A7: =RANK(D7,$D$5:$D$55) -> 3 | B7: Trinity Valley Rhodesian Ridgeback Club of Texas | C7: =COUNTIFS(Trials!$C$2:$C$149,B7,Trials!$H$2:$H$149,">=0") -> 4 | D7: =SUMIF(Trials!$C$2:$C$149,B7,Trials!$H$2:$H$149) -> 213 | E7: =D7/C7 -> 53.25 | F7: =SUMPRODUCT(MAX((Trials!$C$2:$C$149=B7)*Trials!$H$2:$H$149)) -> 73 | G7: =SUMIF(Trials!$C$2:$C$149,B7,Trials!$J$2:$J$149) -> 17
A8: =RANK(D8,$D$5:$D$55) -> 4 | B8: Northwest Rhodesian Ridgeback Club | C8: =COUNTIFS(Trials!$C$2:$C$149,B8,Trials!$H$2:$H$149,">=0") -> 6 | D8: =SUMIF(Trials!$C$2:$C$149,B8,Trials!$H$2:$H$149) -> 207 | E8: =D8/C8 -> 34.5 | F8: =SUMPRODUCT(MAX((Trials!$C$2:$C$149=B8)*Trials!$H$2:$H$149)) -> 38 | G8: =SUMIF(Trials!$C$2:$C$149,B8,Trials!$J$2:$J$149) -> 39
A9: =RANK(D9,$D$5:$D$55) -> 5 | B9: Desert Fun Bunch Sighthound Club | C9: =COUNTIFS(Trials!$C$2:$C$149,B9,Trials!$H$2:$H$149,">=0") -> 4 | D9: =SUMIF(Trials!$C$2:$C$149,B9,Trials!$H$2:$H$149) -> 182 | E9: =D9/C9 -> 45.5 | F9: =SUMPRODUCT(MAX((Trials!$C$2:$C$149=B9)*Trials!$H$2:$H$149)) -> 54 | G9: =SUMIF(Trials!$C$2:$C$149,B9,Trials!$J$2:$J$149) -> 17
A10: =RANK(D10,$D$5:$D$55) -> 6 | B10: Greater Ocala-Gainesville Lure Coursing Association | C10: =COUNTIFS(Trials!$C$2:$C$149,B10,Trials!$H$2:$H$149,">=0") -> 4 | D10: =SUMIF(Trials!$C$2:$C$149,B10,Trials!$H$2:$H$149) -> 176 | E10: =D10/C10 -> 44 | F10: =SUMPRODUCT(MAX((Trials!$C$2:$C$149=B10)*Trials!$H$2:$H$149)) -> 52 | G10: =SUMIF(Trials!$C$2:$C$149,B10,Trials!$J$2:$J$149) -> 12
A11: =RANK(D11,$D$5:$D$55) -> 7 | B11: Evergreen Basenji Club | C11: =COUNTIFS(Trials!$C$2:$C$149,B11,Trials!$H$2:$H$149,">=0") -> 4 | D11: =SUMIF(Trials!$C$2:$C$149,B11,Trials!$H$2:$H$149) -> 146 | E11: =D11/C11 -> 36.5 | F11: =SUMPRODUCT(MAX((Trials!$C$2:$C$149=B11)*Trials!$H$2:$H$149)) -> 49 | G11: =SUMIF(Trials!$C$2:$C$149,B11,Trials!$J$2:$J$149) -> 39
A12: =RANK(D12,$D$5:$D$55) -> 8 | B12: Midwest Borzoi Club | C12: =COUNTIFS(Trials!$C$2:$C$149,B12,Trials!$H$2:$H$149,">=0") -> 2 | D12: =SUMIF(Trials!$C$2:$C$149,B12,Trials!$H$2:$H$149) -> 131 | E12: =D12/C12 -> 65.5 | F12: =SUMPRODUCT(MAX((Trials!$C$2:$C$149=B12)*Trials!$H$2:$H$149)) -> 67 | G12: =SUMIF(Trials!$C$2:$C$149,B12,Trials!$J$2:$J$149) -> 29
A13: =RANK(D13,$D$5:$D$55) -> 9 | B13: Iowa Coursing Association | C13: =COUNTIFS(Trials!$C$2:$C$149,B13,Trials!$H$2:$H$149,">=0") -> 3 | D13: =SUMIF(Trials!$C$2:$C$149,B13,Trials!$H$2:$H$149) -> 120 | E13: =D13/C13 -> 40 | F13: =SUMPRODUCT(MAX((Trials!$C$2:$C$149=B13)*Trials!$H$2:$H$149)) -> 43 | G13: =SUMIF(Trials!$C$2:$C$149,B13,Trials!$J$2:$J$149) -> 1
A14: =RANK(D14,$D$5:$D$55) -> 9 | B14: Northern California Whippet Fanciers Association | C14: =COUNTIFS(Trials!$C$2:$C$149,B14,Trials!$H$2:$H$149,">=0") -> 2 | D14: =SUMIF(Trials!$C$2:$C$149,B14,Trials!$H$2:$H$149) -> 120 | E14: =D14/C14 -> 60 | F14: =SUMPRODUCT(MAX((Trials!$C$2:$C$149=B14)*Trials!$H$2:$H$149)) -> 61 | G14: =SUMIF(Trials!$C$2:$C$149,B14,Trials!$J$2:$J$149) -> 22
A15: =RANK(D15,$D$5:$D$55) -> 11 | B15: American Whippet Club, Inc. | C15: =COUNTIFS(Trials!$C$2:$C$149,B15,Trials!$H$2:$H$149,">=0") -> 2 | D15: =SUMIF(Trials!$C$2:$C$149,B15,Trials!$H$2:$H$149) -> 114 | E15: =D15/C15 -> 57 | F15: =SUMPRODUCT(MAX((Trials!$C$2:$C$149=B15)*Trials!$H$2:$H$149)) -> 77 | G15: =SUMIF(Trials!$C$2:$C$149,B15,Trials!$J$2:$J$149) -> 0
A16: =RANK(D16,$D$5:$D$55) -> 12 | B16: Minnesota Coursing Association | C16: =COUNTIFS(Trials!$C$2:$C$149,B16,Trials!$H$2:$H$149,">=0") -> 4 | D16: =SUMIF(Trials!$C$2:$C$149,B16,Trials!$H$2:$H$149) -> 112 | E16: =D16/C16 -> 28 | F16: =SUMPRODUCT(MAX((Trials!$C$2:$C$149=B16)*Trials!$H$2:$H$149)) -> 38 | G16: =SUMIF(Trials!$C$2:$C$149,B16,Trials!$J$2:$J$149) -> 28
... A55: =RANK(D55,$D$5:$D$55) -> 50 | B55: Scottish Deerhound Club of America, Inc. | C55: =COUNTIFS(Trials!$C$2:$C$149,B55,Trials!$H$2:$H$149,">=0") -> 1 | D55: =SUMIF(Trials!$C$2:$C$149,B55,Trials!$H$2:$H$149) -> 13 | E55: =D55/C55 -> 13 | F55: =SUMPRODUCT(MAX((Trials!$C$2:$C$149=B55)*Trials!$H$2:$H$149)) -> 13 | G55: =SUMIF(Trials!$C$2:$C$149,B55,Trials!$J$2:$J$149) -> 4

Sheet State ranking
A1: States ranked by total LC Trial entries
A2: States whose only events have no results posted yet (GA, IL) are not ranked.
A4: Rank | B4: State | C4: Trials held | D4: LC Trial entries | E4: Avg per trial | F4: Largest trial | G4: LC Test entries
A5: =RANK(D5,$D$5:$D$29) -> 1 | B5: WA | C5: =COUNTIFS(Trials!$E$2:$E$149,B5,Trials!$H$2:$H$149,">=0") -> 15 | D5: =SUMIF(Trials!$E$2:$E$149,B5,Trials!$H$2:$H$149) -> 572 | E5: =D5/C5 -> 38.133333 | F5: =SUMPRODUCT(MAX((Trials!$E$2:$E$149=B5)*Trials!$H$2:$H$149)) -> 77 | G5: =SUMIF(Trials!$E$2:$E$149,B5,Trials!$J$2:$J$149) -> 94
A6: =RANK(D6,$D$5:$D$29) -> 2 | B6: TX | C6: =COUNTIFS(Trials!$E$2:$E$149,B6,Trials!$H$2:$H$149,">=0") -> 10 | D6: =SUMIF(Trials!$E$2:$E$149,B6,Trials!$H$2:$H$149) -> 433 | E6: =D6/C6 -> 43.3 | F6: =SUMPRODUCT(MAX((Trials!$E$2:$E$149=B6)*Trials!$H$2:$H$149)) -> 73 | G6: =SUMIF(Trials!$E$2:$E$149,B6,Trials!$J$2:$J$149) -> 51
A7: =RANK(D7,$D$5:$D$29) -> 3 | B7: FL | C7: =COUNTIFS(Trials!$E$2:$E$149,B7,Trials!$H$2:$H$149,">=0") -> 10 | D7: =SUMIF(Trials!$E$2:$E$149,B7,Trials!$H$2:$H$149) -> 420 | E7: =D7/C7 -> 42 | F7: =SUMPRODUCT(MAX((Trials!$E$2:$E$149=B7)*Trials!$H$2:$H$149)) -> 52 | G7: =SUMIF(Trials!$E$2:$E$149,B7,Trials!$J$2:$J$149) -> 42
A8: =RANK(D8,$D$5:$D$29) -> 4 | B8: CA | C8: =COUNTIFS(Trials!$E$2:$E$149,B8,Trials!$H$2:$H$149,">=0") -> 10 | D8: =SUMIF(Trials!$E$2:$E$149,B8,Trials!$H$2:$H$149) -> 372 | E8: =D8/C8 -> 37.2 | F8: =SUMPRODUCT(MAX((Trials!$E$2:$E$149=B8)*Trials!$H$2:$H$149)) -> 61 | G8: =SUMIF(Trials!$E$2:$E$149,B8,Trials!$J$2:$J$149) -> 59
A9: =RANK(D9,$D$5:$D$29) -> 5 | B9: MI | C9: =COUNTIFS(Trials!$E$2:$E$149,B9,Trials!$H$2:$H$149,">=0") -> 7 | D9: =SUMIF(Trials!$E$2:$E$149,B9,Trials!$H$2:$H$149) -> 331 | E9: =D9/C9 -> 47.285714 | F9: =SUMPRODUCT(MAX((Trials!$E$2:$E$149=B9)*Trials!$H$2:$H$149)) -> 77 | G9: =SUMIF(Trials!$E$2:$E$149,B9,Trials!$J$2:$J$149) -> 39
A10: =RANK(D10,$D$5:$D$29) -> 6 | B10: AZ | C10: =COUNTIFS(Trials!$E$2:$E$149,B10,Trials!$H$2:$H$149,">=0") -> 8 | D10: =SUMIF(Trials!$E$2:$E$149,B10,Trials!$H$2:$H$149) -> 281 | E10: =D10/C10 -> 35.125 | F10: =SUMPRODUCT(MAX((Trials!$E$2:$E$149=B10)*Trials!$H$2:$H$149)) -> 54 | G10: =SUMIF(Trials!$E$2:$E$149,B10,Trials!$J$2:$J$149) -> 44
A11: =RANK(D11,$D$5:$D$29) -> 7 | B11: OH | C11: =COUNTIFS(Trials!$E$2:$E$149,B11,Trials!$H$2:$H$149,">=0") -> 4 | D11: =SUMIF(Trials!$E$2:$E$149,B11,Trials!$H$2:$H$149) -> 229 | E11: =D11/C11 -> 57.25 | F11: =SUMPRODUCT(MAX((Trials!$E$2:$E$149=B11)*Trials!$H$2:$H$149)) -> 67 | G11: =SUMIF(Trials!$E$2:$E$149,B11,Trials!$J$2:$J$149) -> 45
A12: =RANK(D12,$D$5:$D$29) -> 8 | B12: NJ | C12: =COUNTIFS(Trials!$E$2:$E$149,B12,Trials!$H$2:$H$149,">=0") -> 8 | D12: =SUMIF(Trials!$E$2:$E$149,B12,Trials!$H$2:$H$149) -> 183 | E12: =D12/C12 -> 22.875 | F12: =SUMPRODUCT(MAX((Trials!$E$2:$E$149=B12)*Trials!$H$2:$H$149)) -> 31 | G12: =SUMIF(Trials!$E$2:$E$149,B12,Trials!$J$2:$J$149) -> 36
A13: =RANK(D13,$D$5:$D$29) -> 9 | B13: PA | C13: =COUNTIFS(Trials!$E$2:$E$149,B13,Trials!$H$2:$H$149,">=0") -> 6 | D13: =SUMIF(Trials!$E$2:$E$149,B13,Trials!$H$2:$H$149) -> 150 | E13: =D13/C13 -> 25 | F13: =SUMPRODUCT(MAX((Trials!$E$2:$E$149=B13)*Trials!$H$2:$H$149)) -> 35 | G13: =SUMIF(Trials!$E$2:$E$149,B13,Trials!$J$2:$J$149) -> 28
A14: =RANK(D14,$D$5:$D$29) -> 10 | B14: VA | C14: =COUNTIFS(Trials!$E$2:$E$149,B14,Trials!$H$2:$H$149,">=0") -> 4 | D14: =SUMIF(Trials!$E$2:$E$149,B14,Trials!$H$2:$H$149) -> 134 | E14: =D14/C14 -> 33.5 | F14: =SUMPRODUCT(MAX((Trials!$E$2:$E$149=B14)*Trials!$H$2:$H$149)) -> 42 | G14: =SUMIF(Trials!$E$2:$E$149,B14,Trials!$J$2:$J$149) -> 21
A15: =RANK(D15,$D$5:$D$29) -> 11 | B15: IA | C15: =COUNTIFS(Trials!$E$2:$E$149,B15,Trials!$H$2:$H$149,">=0") -> 3 | D15: =SUMIF(Trials!$E$2:$E$149,B15,Trials!$H$2:$H$149) -> 120 | E15: =D15/C15 -> 40 | F15: =SUMPRODUCT(MAX((Trials!$E$2:$E$149=B15)*Trials!$H$2:$H$149)) -> 43 | G15: =SUMIF(Trials!$E$2:$E$149,B15,Trials!$J$2:$J$149) -> 1
A16: =RANK(D16,$D$5:$D$29) -> 12 | B16: MN | C16: =COUNTIFS(Trials!$E$2:$E$149,B16,Trials!$H$2:$H$149,">=0") -> 4 | D16: =SUMIF(Trials!$E$2:$E$149,B16,Trials!$H$2:$H$149) -> 112 | E16: =D16/C16 -> 28 | F16: =SUMPRODUCT(MAX((Trials!$E$2:$E$149=B16)*Trials!$H$2:$H$149)) -> 38 | G16: =SUMIF(Trials!$E$2:$E$149,B16,Trials!$J$2:$J$149) -> 28
... A29: =RANK(D29,$D$5:$D$29) -> 25 | B29: MT | C29: =COUNTIFS(Trials!$E$2:$E$149,B29,Trials!$H$2:$H$149,">=0") -> 2 | D29: =SUMIF(Trials!$E$2:$E$149,B29,Trials!$H$2:$H$149) -> 19 | E29: =D29/C29 -> 9.5 | F29: =SUMPRODUCT(MAX((Trials!$E$2:$E$149=B29)*Trials!$H$2:$H$149)) -> 11 | G29: =SUMIF(Trials!$E$2:$E$149,B29,Trials!$J$2:$J$149) -> 9

Sheet Notes
A1: How to read this workbook
A2: Each row on the Trials sheet is one AKC event number. Counts are copied from the "Number of Entries" and "Number of Competitors" lines on that event's AKC results page; the link in the last column opens it.
A3: LC Trial = the trial stakes (Open, Specials, Veterans). This is the figure comparable to an ASFA trial entry.
A4: LC Test = Junior Courser and Qualified Courser tests held with the trial. A test entry of 0 means the test was offered and nobody entered. A blank means that event had no test (or no trial).
A5: Entries and competitors are AKC's own labels. Competitors is the lower figure where the two differ.
A6: Scope: "All-breed" events are open to all eligible sighthound breeds. A breed name marks a specialty limited to that breed.
A7: Results posted = No: AKC had not posted results for that event when this was collected (events from September 7 onward, 25 in all). Their entry cells are blank and they are left out of every total. Re-collect later to fill them in.
A8: Excluded: Coursing Ability Tests (CAT) and Fast CAT, which AKC lists as separate event types.
A9: Totals on the Summary sheet are formulas over the Trials sheet and update if rows are edited or added.
A10: Ranking sheets are ordered as of collection. Their figures are formulas, but the row order does not re-sort itself if the Trials sheet is edited.
